Workbook

Sheet Start here
A1: Sprint 53 - Set B translation review (English → Mandarin)
A3: What you are doing | B3: Checking translations we wrote to test automatic (LLM) translation judges. For each row, tell us if the row is what it claims to be, and what quality band you would give it. Read SetB_Reviewer_Instructions.docx first (about 10 minutes).
A4: Rows to review | B4: 265 rows on the 'Review' tab, grouped by English sentence (40 sentences). Expect about 1 minute per row; it is fine to work in several sittings.
A5: Where to type | B5: ONLY in the yellow columns M-R. Grey and white columns are pre-filled - please do not edit them. Column S fills itself in.
A6: Q1 Row matches its description? | B6: Yes / No / Partly / Not sure. Column I says what the row is supposed to be.
A7: Q2 Your quality band | B7: clean / moderate / poor - your own judgement of the candidate (definitions below).
A8: Q3 Planted error severity | B8: Only for rows with a planted error (columns J-K): minor / major / critical, or 'not an error' if you think it is actually acceptable. 'n/a' is pre-filled where there is no planted error.
A9: Q4 Other errors | B9: Any error we did not plant or describe. Quote the Chinese text and say why.
A10: Q5 Suggested correction | B10: Only if the row is wrong for its purpose. Write the FULL corrected sentence. For gold rows this becomes the new reference.
A11: Band: clean | B11: Correct meaning, natural Chinese. You would publish it with at most tiny edits.
A12: Band: moderate | B12: Meaning is essentially right, but it is stiff, unnatural, slightly off in tone, or has small errors a reader would notice.
A13: Band: poor | B13: At least one meaning error that would mislead a reader, or the sentence does not make sense.
A14: Traditional-script rows | B14: You are not expected to be a Traditional-script expert. Check the meaning; answer 'Not sure' in Q1 about Taiwan word choice if unfamiliar.
A15: When finished | B15: Save the file with your initials in the name (e.g. SetB_Review_Workbook_LW.xlsx) and send it back. The 'Summary' tab shows your progress.
A17: Example of a completed row
A18: Row type | B18: fluent_wrong
A19: English source | B19: The museum opens at nine every morning.
A20: Candidate translation | B20: 博物馆每天晚上九点开门。
A21: Planted error | B21: 晚上 - [Mistranslation, major] 'Morning' becomes 'evening'.
A22: Q1. Row matches its description? | B22: Yes
A23: Q2. Your quality band | B23: poor
A24: Q3. Planted error severity | B24: major
A25: Q4. Other errors you found | B25: (blank - none)
A26: Q5. Suggested correction | B26: (blank - the error is intentional, do not correct it)
A27: Comments | B27: Reads naturally, so a careless reader would be misled.

Sheet Review
A1: item_id | B1: Source ID | C1: Category | D1: Row type | E1: Script | F1: English source | G1: Candidate translation (CHECK THIS) | H1: Gold reference (for comparison) | I1: What this row is supposed to be | J1: Planted error - text | K1: Planted error - what is wrong | L1: Our expected band | M1: Q1. Row matches its description? | N1: Q2. Your quality band | O1: Q3. Planted error severity | P1: Q4. Other errors you found | Q1: Q5. Suggested correction (full sentence) | R1: Comments | S1: Band agrees? (auto)
A2: B::S52_001::gold | B2: S52_001 | C2: simple_control | D2: gold | E2: simplified | F2: Let's try it. | G2: 我们试试吧。 | H2: 我们试试吧。 | I2: PROPOSED REFERENCE. Should be a fully correct, natural Mainland Mandarin translation. If anything is wrong or unnatural, write a corrected sentence in column Q - it will become the reference for every row of this source. | L2: clean | M2: Yes | N2: clean | O2: n/a | S2: =IF(N2="","",IF(N2=L2,"agree","DISAGREE")) -> agree
A3: B::S52_001::paraphrase | B3: S52_001 | C3: simple_control | D3: paraphrase | E3: simplified | F3: Let's try it. | G3: 咱们来试一下。 | H3: 我们试试吧。 | I3: Should mean EXACTLY the same as the gold row, using deliberately different wording. Check nothing is added, lost or changed, and that it sounds natural. | L3: clean | M3: Yes | N3: clean | O3: n/a | S3: =IF(N3="","",IF(N3=L3,"agree","DISAGREE")) -> agree
A4: B::S52_001::literal | B4: S52_001 | C4: simple_control | D4: literal | E4: simplified | F4: Let's try it. | G4: 让我们尝试它。 | H4: 我们试试吧。 | I4: Should have NO meaning errors, but be stiff / word-for-word on purpose. Stiffness is intended - only flag meaning problems or ungrammatical Chinese. | L4: moderate | M4: Yes | N4: moderate | O4: n/a | S4: =IF(N4="","",IF(N4=L4,"agree","DISAGREE")) -> agree
A5: B::S52_001::fluent_wrong | B5: S52_001 | C5: simple_control | D5: fluent_wrong | E5: simplified | F5: Let's try it. | G5: 我们别试了吧。 | H5: 我们试试吧。 | I5: Should read naturally but contain exactly ONE planted meaning error (columns J-K). Check the error is real and that there is no OTHER error. | J5: 别试了 | K5: [Mistranslation, major] Suggestion to try becomes suggestion NOT to try (polarity reversed). | L5: poor | M5: Yes | N5: poor | O5: major | S5: =IF(N5="","",IF(N5=L5,"agree","DISAGREE")) -> agree
A6: B::S52_001::targeted_error | B6: S52_001 | C6: simple_control | D6: targeted_error | E6: simplified | F6: Let's try it. | G6: 我们已经试过了。 | H6: 我们试试吧。 | I6: Contains exactly ONE planted error typical of this category (columns J-K). Check the error is real and that there is no OTHER error. | J6: 已经试过了 | K6: [Mistranslation, major] Proposal ('let's try') becomes a statement about the past ('we already tried'). | L6: poor | M6: Yes | N6: poor | O6: major | S6: =IF(N6="","",IF(N6=L6,"agree","DISAGREE")) -> agree
A7: B::S52_001::original_candidate | B7: S52_001 | C7: simple_control | D7: original_candidate | E7: simplified | F7: Let's try it. | G7: 我们试一下吧。 | H7: 我们试试吧。 | I7: Existing Sprint 52 machine translation, not written for this sprint. We only need your quality band and any errors you see. | L7: clean | M7: Yes | N7: clean | O7: n/a | S7: =IF(N7="","",IF(N7=L7,"agree","DISAGREE")) -> agree
A8: B::S52_002::gold | B8: S52_002 | C8: simple_control | D8: gold | E8: simplified | F8: I have to go to sleep. | G8: 我得去睡觉了。 | H8: 我得去睡觉了。 | I8: PROPOSED REFERENCE. Should be a fully correct, natural Mainland Mandarin translation. If anything is wrong or unnatural, write a corrected sentence in column Q - it will become the reference for every row of this source. | L8: clean | M8: Yes | N8: clean | O8: n/a | S8: =IF(N8="","",IF(N8=L8,"agree","DISAGREE")) -> agree
A9: B::S52_002::paraphrase | B9: S52_002 | C9: simple_control | D9: paraphrase | E9: simplified | F9: I have to go to sleep. | G9: 我必须上床休息了。 | H9: 我得去睡觉了。 | I9: Should mean EXACTLY the same as the gold row, using deliberately different wording. Check nothing is added, lost or changed, and that it sounds natural. | L9: clean | M9: Yes | N9: clean | O9: n/a | S9: =IF(N9="","",IF(N9=L9,"agree","DISAGREE")) -> agree
A10: B::S52_002::literal | B10: S52_002 | C10: simple_control | D10: literal | E10: simplified | F10: I have to go to sleep. | G10: 我有去睡觉的必要。 | H10: 我得去睡觉了。 | I10: Should have NO meaning errors, but be stiff / word-for-word on purpose. Stiffness is intended - only flag meaning problems or ungrammatical Chinese. | L10: moderate | M10: Yes | N10: moderate | O10: n/a | S10: =IF(N10="","",IF(N10=L10,"agree","DISAGREE")) -> agree
A11: B::S52_002::fluent_wrong | B11: S52_002 | C11: simple_control | D11: fluent_wrong | E11: simplified | F11: I have to go to sleep. | G11: 我不想去睡觉。 | H11: 我得去睡觉了。 | I11: Should read naturally but contain exactly ONE planted meaning error (columns J-K). Check the error is real and that there is no OTHER error. | J11: 不想 | K11: [Mistranslation, major] 'Have to' becomes 'don't want to'. | L11: poor | M11: Yes | N11: poor | O11: major | S11: =IF(N11="","",IF(N11=L11,"agree","DISAGREE")) -> agree
A12: B::S52_002::targeted_error | B12: S52_002 | C12: simple_control | D12: targeted_error | E12: simplified | F12: I have to go to sleep. | G12: 我得去上班了。 | H12: 我得去睡觉了。 | I12: Contains exactly ONE planted error typical of this category (columns J-K). Check the error is real and that there is no OTHER error. | J12: 上班 | K12: [Mistranslation, major] 'Sleep' becomes 'go to work'. | L12: poor | M12: Yes | N12: poor | O12: major | S12: =IF(N12="","",IF(N12=L12,"agree","DISAGREE")) -> agree
A13: B::S52_002::original_candidate | B13: S52_002 | C13: simple_control | D13: original_candidate | E13: simplified | F13: I have to go to sleep. | G13: 我得去睡觉了。 | H13: 我得去睡觉了。 | I13: Existing Sprint 52 machine translation, not written for this sprint. We only need your quality band and any errors you see. | L13: clean | M13: Yes | N13: clean | O13: n/a | S13: =IF(N13="","",IF(N13=L13,"agree","DISAGREE")) -> agree
A14: B::S52_005::gold | B14: S52_005 | C14: simple_control | D14: gold | E14: simplified | F14: I will be back soon. | G14: 我很快就回来。 | H14: 我很快就回来。 | I14: PROPOSED REFERENCE. Should be a fully correct, natural Mainland Mandarin translation. If anything is wrong or unnatural, write a corrected sentence in column Q - it will become the reference for every row of this source. | L14: clean | M14: Yes | N14: clean | O14: n/a | S14: =IF(N14="","",IF(N14=L14,"agree","DISAGREE")) -> agree
A15: B::S52_005::paraphrase | B15: S52_005 | C15: simple_control | D15: paraphrase | E15: simplified | F15: I will be back soon. | G15: 我去去就来。 | H15: 我很快就回来。 | I15: Should mean EXACTLY the same as the gold row, using deliberately different wording. Check nothing is added, lost or changed, and that it sounds natural. | L15: clean | M15: Yes | N15: clean | O15: n/a | S15: =IF(N15="","",IF(N15=L15,"agree","DISAGREE")) -> agree
A16: B::S52_005::literal | B16: S52_005 | C16: simple_control | D16: literal | E16: simplified | F16: I will be back soon. | G16: 我将会很快地回来。 | H16: 我很快就回来。 | I16: Should have NO meaning errors, but be stiff / word-for-word on purpose. Stiffness is intended - only flag meaning problems or ungrammatical Chinese. | L16: moderate | M16: Yes | N16: moderate | O16: n/a | S16: =IF(N16="","",IF(N16=L16,"agree","DISAGREE")) -> agree
A17: B::S52_005::fluent_wrong | B17: S52_005 | C17: simple_control | D17: fluent_wrong | E17: simplified | F17: I will be back soon. | G17: 我很快就走。 | H17: 我很快就回来。 | I17: Should read naturally but contain exactly ONE planted meaning error (columns J-K). Check the error is real and that there is no OTHER error. | J17: 走 | K17: [Mistranslation, major] 'Be back' becomes 'leave'. | L17: poor | M17: Yes | N17: poor | O17: major | S17: =IF(N17="","",IF(N17=L17,"agree","DISAGREE")) -> agree
A18: B::S52_005::targeted_error | B18: S52_005 | C18: simple_control | D18: targeted_error | E18: simplified | F18: I will be back soon. | G18: 我明天就回来。 | H18: 我很快就回来。 | I18: Contains exactly ONE planted error typical of this category (columns J-K). Check the error is real and that there is no OTHER error. | J18: 明天 | K18: [Mistranslation, major] 'Soon' becomes 'tomorrow'. | L18: poor | M18: Yes | N18: poor | O18: major | S18: =IF(N18="","",IF(N18=L18,"agree","DISAGREE")) -> agree
A19: B::S52_005::original_candidate | B19: S52_005 | C19: simple_control | D19: original_candidate | E19: simplified | F19: I will be back soon. | G19: 我很快就会回来。 | H19: 我很快就回来。 | I19: Existing Sprint 52 machine translation, not written for this sprint. We only need your quality band and any errors you see. | L19: clean | M19: Yes | N19: clean | O19: n/a | S19: =IF(N19="","",IF(N19=L19,"agree","DISAGREE")) -> agree
A20: B::S52_008::gold | B20: S52_008 | C20: simple_control | D20: gold | E20: simplified | F20: Our flight was delayed because of the storm. | G20: 因为暴风雨，我们的航班延误了。 | H20: 因为暴风雨，我们的航班延误了。 | I20: PROPOSED REFERENCE. Should be a fully correct, natural Mainland Mandarin translation. If anything is wrong or unnatural, write a corrected sentence in column Q - it will become the reference for every row of this source. | L20: clean | M20: Yes | N20: clean | O20: n/a | S20: =IF(N20="","",IF(N20=L20,"agree","DISAGREE")) -> agree
A21: B::S52_008::paraphrase | B21: S52_008 | C21: simple_control | D21: paraphrase | E21: simplified | F21: Our flight was delayed because of the storm. | G21: 受风暴影响，我们的班机晚点了。 | H21: 因为暴风雨，我们的航班延误了。 | I21: Should mean EXACTLY the same as the gold row, using deliberately different wording. Check nothing is added, lost or changed, and that it sounds natural. | L21: clean | M21: Yes | N21: clean | O21: n/a | S21: =IF(N21="","",IF(N21=L21,"agree","DISAGREE")) -> agree
A22: B::S52_008::literal | B22: S52_008 | C22: simple_control | D22: literal | E22: simplified | F22: Our flight was delayed because of the storm. | G22: 我们的航班被延误了因为暴风雨。 | H22: 因为暴风雨，我们的航班延误了。 | I22: Should have NO meaning errors, but be stiff / word-for-word on purpose. Stiffness is intended - only flag meaning problems or ungrammatical Chinese. | L22: moderate | M22: Yes | N22: moderate | O22: n/a | S22: =IF(N22="","",IF(N22=L22,"agree","DISAGREE")) -> agree
A23: B::S52_008::padded | B23: S52_008 | C23: simple_control | D23: padded | E23: simplified | F23: Our flight was delayed because of the storm. | G23: 由于遇上了暴风雨天气的原因，我们所乘坐的这趟航班最终出现了延误的情况。 | H23: 因为暴风雨，我们的航班延误了。 | I23: Same meaning as gold, deliberately wordy/redundant. Check no meaning was added or lost. | L23: clean | M23: Yes | N23: clean | O23: n/a | S23: =IF(N23="","",IF(N23=L23,"agree","DISAGREE")) -> agree
A24: B::S52_008::fluent_wrong | B24: S52_008 | C24: simple_control | D24: fluent_wrong | E24: simplified | F24: Our flight was delayed because of the storm. | G24: 因为暴风雨，我们的航班取消了。 | H24: 因为暴风雨，我们的航班延误了。 | I24: Should read naturally but contain exactly ONE planted meaning error (columns J-K). Check the error is real and that there is no OTHER error. | J24: 取消 | K24: [Mistranslation, major] 'Delayed' becomes 'cancelled'. | L24: poor | M24: Yes | N24: poor | O24: major | S24: =IF(N24="","",IF(N24=L24,"agree","DISAGREE")) -> agree
A25: B::S52_008::targeted_error | B25: S52_008 | C25: simple_control | D25: targeted_error | E25: simplified | F25: Our flight was delayed because of the storm. | G25: 因为暴风雪，我们的航班延误了。 | H25: 因为暴风雨，我们的航班延误了。 | I25: Contains exactly ONE planted error typical of this category (columns J-K). Check the error is real and that there is no OTHER error. | J25: 暴风雪 | K25: [Mistranslation, major] 'Storm' becomes 'snowstorm/blizzard'. | L25: poor | M25: Yes | N25: poor | O25: major | S25: =IF(N25="","",IF(N25=L25,"agree","DISAGREE")) -> agree
A26: B::S52_008::original_candidate | B26: S52_008 | C26: simple_control | D26: original_candidate | E26: simplified | F26: Our flight was delayed because of the storm. | G26: 我们的航班因为暴风雨延误了。 | H26: 因为暴风雨，我们的航班延误了。 | I26: Existing Sprint 52 machine translation, not written for this sprint. We only need your quality band and any errors you see. | L26: clean | M26: Yes | N26: clean | O26: n/a | S26: =IF(N26="","",IF(N26=L26,"agree","DISAGREE")) -> agree
A27: B::S52_006::gold | B27: S52_006 | C27: numbers_units_dates | D27: gold | E27: simplified | F27: The museum opens at nine every morning. | G27: 博物馆每天早上九点开门。 | H27: 博物馆每天早上九点开门。 | I27: PROPOSED REFERENCE. Should be a fully correct, natural Mainland Mandarin translation. If anything is wrong or unnatural, write a corrected sentence in column Q - it will become the reference for every row of this source. | L27: clean | M27: Yes | N27: clean | O27: n/a | S27: =IF(N27="","",IF(N27=L27,"agree","DISAGREE")) -> agree
A28: B::S52_006::paraphrase | B28: S52_006 | C28: numbers_units_dates | D28: paraphrase | E28: simplified | F28: The museum opens at nine every morning. | G28: 这家博物馆每日上午9时开放。 | H28: 博物馆每天早上九点开门。 | I28: Should mean EXACTLY the same as the gold row, using deliberately different wording. Check nothing is added, lost or changed, and that it sounds natural. | L28: clean | M28: Yes | N28: clean | O28: n/a | S28: =IF(N28="","",IF(N28=L28,"agree","DISAGREE")) -> agree
A29: B::S52_006::literal | B29: S52_006 | C29: numbers_units_dates | D29: literal | E29: simplified | F29: The museum opens at nine every morning. | G29: 博物馆在每一个早晨的九点钟打开。 | H29: 博物馆每天早上九点开门。 | I29: Should have NO meaning errors, but be stiff / word-for-word on purpose. Stiffness is intended - only flag meaning problems or ungrammatical Chinese. | L29: moderate | M29: Yes | N29: moderate | O29: n/a | S29: =IF(N29="","",IF(N29=L29,"agree","DISAGREE")) -> agree
A30: B::S52_006::fluent_wrong | B30: S52_006 | C30: numbers_units_dates | D30: fluent_wrong | E30: simplified | F30: The museum opens at nine every morning. | G30: 博物馆每天晚上九点开门。 | H30: 博物馆每天早上九点开门。 | I30: Should read naturally but contain exactly ONE planted meaning error (columns J-K). Check the error is real and that there is no OTHER error. | J30: 晚上 | K30: [Mistranslation, major] 'Morning' becomes 'evening'. | L30: poor | M30: Yes | N30: poor | O30: major | S30: =IF(N30="","",IF(N30=L30,"agree","DISAGREE")) -> agree
A31: B::S52_006::targeted_error | B31: S52_006 | C31: numbers_units_dates | D31: targeted_error | E31: simplified | F31: The museum opens at nine every morning. | G31: 博物馆每天早上十点开门。 | H31: 博物馆每天早上九点开门。 | I31: Contains exactly ONE planted error typical of this category (columns J-K). Check the error is real and that there is no OTHER error. | J31: 十点 | K31: [Mistranslation, major] Nine o'clock becomes ten o'clock. | L31: poor | M31: Yes | N31: poor | O31: major | S31: =IF(N31="","",IF(N31=L31,"agree","DISAGREE")) -> agree
A32: B::S52_006::original_candidate | B32: S52_006 | C32: numbers_units_dates | D32: original_candidate | E32: simplified | F32: The museum opens at nine every morning. | G32: 博物馆每天早上九点开门。 | H32: 博物馆每天早上九点开门。 | I32: Existing Sprint 52 machine translation, not written for this sprint. We only need your quality band and any errors you see. | L32: clean | M32: Yes | N32: clean | O32: n/a | S32: =IF(N32="","",IF(N32=L32,"agree","DISAGREE")) -> agree
A33: B::S52_006::traditional_char | B33: S52_006 | C33: numbers_units_dates | D33: traditional_char | E33: traditional_char | F33: The museum opens at nine every morning. | G33: 博物館每天早上九點開門。 | H33: 博物馆每天早上九点开门。 | I33: Gold converted to Traditional CHARACTERS only - same words. Check the meaning is unchanged and characters look right (e.g. no wrong 裡/里 swaps in names). | L33: clean | M33: Yes | N33: clean | O33: n/a | S33: =IF(N33="","",IF(N33=L33,"agree","DISAGREE")) -> agree
A34: B::A_375::gold | B34: A_375 | C34: numbers_units_dates | D34: gold | E34: simplified | F34: A person who weighs 200 pounds (90kg) on Earth would weigh about 36 pounds (16kg) on Io. So the gravity, of course, pulls less on you. | G34: 一个在地球上重200磅（90千克）的人，到了木卫一上体重只有约36磅（16千克）。因此，那里的引力对你的拉力自然更小。 | H34: 一个在地球上重200磅（90千克）的人，到了木卫一上体重只有约36磅（16千克）。因此，那里的引力对你的拉力自然更小。 | I34: PROPOSED REFERENCE. Should be a fully correct, natural Mainland Mandarin translation. If anything is wrong or unnatural, write a corrected sentence in column Q - it will become the reference for every row of this source. | L34: clean | M34: Yes | N34: clean | O34: n/a | S34: =IF(N34="","",IF(N34=L34,"agree","DISAGREE")) -> agree
A35: B::A_375::paraphrase | B35: A_375 | C35: numbers_units_dates | D35: paraphrase | E35: simplified | F35: A person who weighs 200 pounds (90kg) on Earth would weigh about 36 pounds (16kg) on Io. So the gravity, of course, pulls less on you. | G35: 在地球上体重90公斤（200磅）的人，若站在木卫一上，体重约为16公斤（36磅）——很显然，那里的重力对人的牵引要小得多。 | H35: 一个在地球上重200磅（90千克）的人，到了木卫一上体重只有约36磅（16千克）。因此，那里的引力对你的拉力自然更小。 | I35: Should mean EXACTLY the same as the gold row, using deliberately different wording. Check nothing is added, lost or changed, and that it sounds natural. | L35: clean | M35: Yes | N35: clean | O35: n/a | S35: =IF(N35="","",IF(N35=L35,"agree","DISAGREE")) -> agree
A36: B::A_375::literal | B36: A_375 | C36: numbers_units_dates | D36: literal | E36: simplified | F36: A person who weighs 200 pounds (90kg) on Earth would weigh about 36 pounds (16kg) on Io. So the gravity, of course, pulls less on you. | G36: 一个在地球上称重200磅（90千克）的人，在木卫一上将称重大约36磅（16千克）。所以重力，当然，在你身上拉得更少。 | H36: 一个在地球上重200磅（90千克）的人，到了木卫一上体重只有约36磅（16千克）。因此，那里的引力对你的拉力自然更小。 | I36: Should have NO meaning errors, but be stiff / word-for-word on purpose. Stiffness is intended - only flag meaning problems or ungrammatical Chinese. | L36: moderate | M36: Yes | N36: moderate | O36: n/a | S36: =IF(N36="","",IF(N36=L36,"agree","DISAGREE")) -> agree
A37: B::A_375::fluent_wrong | B37: A_375 | C37: numbers_units_dates | D37: fluent_wrong | E37: simplified | F37: A person who weighs 200 pounds (90kg) on Earth would weigh about 36 pounds (16kg) on Io. So the gravity, of course, pulls less on you. | G37: 一个在地球上重200磅（90千克）的人，到了木卫一上体重只有约36磅（16千克）。因此，那里的引力对你的拉力自然更大。 | H37: 一个在地球上重200磅（90千克）的人，到了木卫一上体重只有约36磅（16千克）。因此，那里的引力对你的拉力自然更小。 | I37: Should read naturally but contain exactly ONE planted meaning error (columns J-K). Check the error is real and that there is no OTHER error. | J37: 更大 | K37: [Mistranslation, major] Gravity pulls 'less' becomes 'more'. | L37: poor | M37: Yes | N37: poor | O37: major | S37: =IF(N37="","",IF(N37=L37,"agree","DISAGREE")) -> agree
A38: B::A_375::targeted_error | B38: A_375 | C38: numbers_units_dates | D38: targeted_error | E38: simplified | F38: A person who weighs 200 pounds (90kg) on Earth would weigh about 36 pounds (16kg) on Io. So the gravity, of course, pulls less on you. | G38: 一个在地球上重200磅（90千克）的人，到了木卫一上体重只有约36千克（16磅）。因此，那里的引力对你的拉力自然更小。 | H38: 一个在地球上重200磅（90千克）的人，到了木卫一上体重只有约36磅（16千克）。因此，那里的引力对你的拉力自然更小。 | I38: Contains exactly ONE planted error typical of this category (columns J-K). Check the error is real and that there is no OTHER error. | J38: 36千克（16磅） | K38: [Mistranslation, major] Units swapped: 36 pounds (16 kg) becomes 36 kg (16 pounds). | L38: poor | M38: Yes | N38: poor | O38: major | S38: =IF(N38="","",IF(N38=L38,"agree","DISAGREE")) -> agree
A39: B::A_375::traditional_char | B39: A_375 | C39: numbers_units_dates | D39: traditional_char | E39: traditional_char | F39: A person who weighs 200 pounds (90kg) on Earth would weigh about 36 pounds (16kg) on Io. So the gravity, of course, pulls less on you. | G39: 一個在地球上重200磅（90千克）的人，到了木衛一上體重只有約36磅（16千克）。因此，那裡的引力對你的拉力自然更小。 | H39: 一个在地球上重200磅（90千克）的人，到了木卫一上体重只有约36磅（16千克）。因此，那里的引力对你的拉力自然更小。 | I39: Gold converted to Traditional CHARACTERS only - same words. Check the meaning is unchanged and characters look right (e.g. no wrong 裡/里 swaps in names). | L39: clean | M39: Yes | N39: clean | O39: n/a | S39: =IF(N39="","",IF(N39=L39,"agree","DISAGREE")) -> agree
A40: B::A_375::traditional_tw | B40: A_375 | C40: numbers_units_dates | D40: traditional_tw | E40: traditional_tw | F40: A person who weighs 200 pounds (90kg) on Earth would weigh about 36 pounds (16kg) on Io. So the gravity, of course, pulls less on you. | G40: 一個在地球上重200磅（90公斤）的人，到了木衛一上體重只有約36磅（16公斤）。因此，那裡的引力對你的拉力自然更小。 | H40: 一个在地球上重200磅（90千克）的人，到了木卫一上体重只有约36磅（16千克）。因此，那里的引力对你的拉力自然更小。 | I40: Gold adapted for Taiwan: Traditional characters + Taiwan vocabulary (e.g. 伺服器, 公尺, 財務長) + 「」 quotes. Check the meaning is unchanged. If you are unsure whether a word is natural in Taiwan, answer 'Not sure' in Q1 rather than guessing. | L40: clean | M40: Yes | N40: clean | O40: n/a | S40: =IF(N40="","",IF(N40=L40,"agree","DISAGREE")) -> agree
...

Sheet Summary
A1: Review progress and agreement with our expected bands (all cells are formulas)
A3: Row type | B3: Rows | C3: Reviewed (Q2 filled) | D3: Band agrees | E3: Agreement rate
A4: gold | B4: =COUNTIF(Review!$D$2:$D$266,A4) -> 40 | C4: =COUNTIFS(Review!$D$2:$D$266,A4,Review!$N$2:$N$266,"<>") -> 40 | D4: =COUNTIFS(Review!$D$2:$D$266,A4,Review!$S$2:$S$266,"agree") -> 40 | E4: =IF(C4=0,"-",D4/C4) -> 1
A5: paraphrase | B5: =COUNTIF(Review!$D$2:$D$266,A5) -> 40 | C5: =COUNTIFS(Review!$D$2:$D$266,A5,Review!$N$2:$N$266,"<>") -> 40 | D5: =COUNTIFS(Review!$D$2:$D$266,A5,Review!$S$2:$S$266,"agree") -> 40 | E5: =IF(C5=0,"-",D5/C5) -> 1
A6: literal | B6: =COUNTIF(Review!$D$2:$D$266,A6) -> 40 | C6: =COUNTIFS(Review!$D$2:$D$266,A6,Review!$N$2:$N$266,"<>") -> 40 | D6: =COUNTIFS(Review!$D$2:$D$266,A6,Review!$S$2:$S$266,"agree") -> 40 | E6: =IF(C6=0,"-",D6/C6) -> 1
A7: padded | B7: =COUNTIF(Review!$D$2:$D$266,A7) -> 5 | C7: =COUNTIFS(Review!$D$2:$D$266,A7,Review!$N$2:$N$266,"<>") -> 5 | D7: =COUNTIFS(Review!$D$2:$D$266,A7,Review!$S$2:$S$266,"agree") -> 5 | E7: =IF(C7=0,"-",D7/C7) -> 1
A8: fluent_wrong | B8: =COUNTIF(Review!$D$2:$D$266,A8) -> 40 | C8: =COUNTIFS(Review!$D$2:$D$266,A8,Review!$N$2:$N$266,"<>") -> 40 | D8: =COUNTIFS(Review!$D$2:$D$266,A8,Review!$S$2:$S$266,"agree") -> 40 | E8: =IF(C8=0,"-",D8/C8) -> 1
A9: targeted_error | B9: =COUNTIF(Review!$D$2:$D$266,A9) -> 40 | C9: =COUNTIFS(Review!$D$2:$D$266,A9,Review!$N$2:$N$266,"<>") -> 40 | D9: =COUNTIFS(Review!$D$2:$D$266,A9,Review!$S$2:$S$266,"agree") -> 40 | E9: =IF(C9=0,"-",D9/C9) -> 1
A10: original_candidate | B10: =COUNTIF(Review!$D$2:$D$266,A10) -> 16 | C10: =COUNTIFS(Review!$D$2:$D$266,A10,Review!$N$2:$N$266,"<>") -> 16 | D10: =COUNTIFS(Review!$D$2:$D$266,A10,Review!$S$2:$S$266,"agree") -> 16 | E10: =IF(C10=0,"-",D10/C10) -> 1
A11: traditional_char | B11: =COUNTIF(Review!$D$2:$D$266,A11) -> 30 | C11: =COUNTIFS(Review!$D$2:$D$266,A11,Review!$N$2:$N$266,"<>") -> 30 | D11: =COUNTIFS(Review!$D$2:$D$266,A11,Review!$S$2:$S$266,"agree") -> 30 | E11: =IF(C11=0,"-",D11/C11) -> 1
A12: traditional_tw | B12: =COUNTIF(Review!$D$2:$D$266,A12) -> 14 | C12: =COUNTIFS(Review!$D$2:$D$266,A12,Review!$N$2:$N$266,"<>") -> 14 | D12: =COUNTIFS(Review!$D$2:$D$266,A12,Review!$S$2:$S$266,"agree") -> 14 | E12: =IF(C12=0,"-",D12/C12) -> 1
A13: TOTAL | B13: =SUM(B4:B12) -> 265 | C13: =SUM(C4:C12) -> 265 | D13: =SUM(D4:D12) -> 265 | E13: =IF(C13=0,"-",D13/C13) -> 1
A15: Q1 answered 'No' or 'Partly': | B15: =COUNTIF(Review!$M$2:$M$266,"No")+COUNTIF(Review!$M$2:$M$266,"Partly") -> 1
A16: Corrections suggested (Q5): | B16: =COUNTIF(Review!$Q$2:$Q$266,"?*") -> 6
